2024-02-21 17:12:39,277 -  nornir.core -     INFO -        run() - Running task 'napalm_get' with args {'getters': ['facts', 'interfaces', 'interfaces_ip']} on 1 hosts
2024-02-21 17:12:39,290 - nornir.core.task -    ERROR -      start() - Host 'Group1-Router1': task 'napalm_get' failed with traceback:
Traceback (most recent call last):
  File "C:\Users\abdullah.naser\AppData\Local\Programs\Python\Python312\Lib\site-packages\netmiko\base_connection.py", line 1137, in establish_connection
    self.remote_conn_pre.connect(**ssh_connect_params)
  File "C:\Users\abdullah.naser\AppData\Local\Programs\Python\Python312\Lib\site-packages\paramiko\client.py", line 377, in connect
    to_try = list(self._families_and_addresses(hostname, port))
             ^^^^^^^^^^^^^^^^^^^^^^^^^^^^^^^^^^^^^^^^^^^^^^^^^^
  File "C:\Users\abdullah.naser\AppData\Local\Programs\Python\Python312\Lib\site-packages\paramiko\client.py", line 202, in _families_and_addresses
    addrinfos = socket.getaddrinfo(
                ^^^^^^^^^^^^^^^^^^^
  File "C:\Users\abdullah.naser\AppData\Local\Programs\Python\Python312\Lib\socket.py", line 963, in getaddrinfo
    for res in _socket.getaddrinfo(host, port, family, type, proto, flags):
               ^^^^^^^^^^^^^^^^^^^^^^^^^^^^^^^^^^^^^^^^^^^^^^^^^^^^^^^^^^^
socket.gaierror: [Errno 11001] getaddrinfo failed

During handling of the above exception, another exception occurred:

Traceback (most recent call last):
  File "C:\Users\abdullah.naser\AppData\Local\Programs\Python\Python312\Lib\site-packages\napalm\base\base.py", line 114, in _netmiko_open
    self._netmiko_device = ConnectHandler(
                           ^^^^^^^^^^^^^^^
  File "C:\Users\abdullah.naser\AppData\Local\Programs\Python\Python312\Lib\site-packages\netmiko\ssh_dispatcher.py", line 399, in ConnectHandler
    return ConnectionClass(*args, **kwargs)
           ^^^^^^^^^^^^^^^^^^^^^^^^^^^^^^^^
  File "C:\Users\abdullah.naser\AppData\Local\Programs\Python\Python312\Lib\site-packages\netmiko\base_connection.py", line 488, in __init__
    self._open()
  File "C:\Users\abdullah.naser\AppData\Local\Programs\Python\Python312\Lib\site-packages\netmiko\base_connection.py", line 493, in _open
    self.establish_connection()
  File "C:\Users\abdullah.naser\AppData\Local\Programs\Python\Python312\Lib\site-packages\netmiko\base_connection.py", line 1159, in establish_connection
    raise NetmikoTimeoutException(msg)
netmiko.exceptions.NetmikoTimeoutException: TCP connection to device failed.

Common causes of this problem are:
1. Incorrect hostname or IP address.
2. Wrong TCP port.
3. Intermediate firewall blocking access.

Device settings: cisco_ios 10.99.1.1/16:22



During handling of the above exception, another exception occurred:

Traceback (most recent call last):
  File "C:\Users\abdullah.naser\AppData\Local\Programs\Python\Python312\Lib\site-packages\nornir\core\task.py", line 99, in start
    r = self.task(self, **self.params)
        ^^^^^^^^^^^^^^^^^^^^^^^^^^^^^^
  File "C:\Users\abdullah.naser\AppData\Local\Programs\Python\Python312\Lib\site-packages\nornir_napalm\plugins\tasks\napalm_get.py", line 32, in napalm_get
    device = task.host.get_connection(CONNECTION_NAME, task.nornir.config)
             ^^^^^^^^^^^^^^^^^^^^^^^^^^^^^^^^^^^^^^^^^^^^^^^^^^^^^^^^^^^^^
  File "C:\Users\abdullah.naser\AppData\Local\Programs\Python\Python312\Lib\site-packages\nornir\core\inventory.py", line 494, in get_connection
    self.open_connection(
  File "C:\Users\abdullah.naser\AppData\Local\Programs\Python\Python312\Lib\site-packages\nornir\core\inventory.py", line 546, in open_connection
    conn_obj.open(
  File "C:\Users\abdullah.naser\AppData\Local\Programs\Python\Python312\Lib\site-packages\nornir_napalm\plugins\connections\__init__.py", line 57, in open
    connection.open()
  File "C:\Users\abdullah.naser\AppData\Local\Programs\Python\Python312\Lib\site-packages\napalm\ios\ios.py", line 172, in open
    self.device = self._netmiko_open(
                  ^^^^^^^^^^^^^^^^^^^
  File "C:\Users\abdullah.naser\AppData\Local\Programs\Python\Python312\Lib\site-packages\napalm\base\base.py", line 123, in _netmiko_open
    raise ConnectionException("Cannot connect to {}".format(self.hostname))
napalm.base.exceptions.ConnectionException: Cannot connect to 10.99.1.1/16

2024-02-21 17:14:07,893 -  nornir.core -     INFO -        run() - Running task 'napalm_get' with args {'getters': ['facts', 'interfaces', 'interfaces_ip']} on 1 hosts
2024-02-21 17:14:17,906 - nornir.core.task -    ERROR -      start() - Host 'Group1-Router1': task 'napalm_get' failed with traceback:
Traceback (most recent call last):
  File "C:\Users\abdullah.naser\AppData\Local\Programs\Python\Python312\Lib\site-packages\netmiko\base_connection.py", line 1137, in establish_connection
    self.remote_conn_pre.connect(**ssh_connect_params)
  File "C:\Users\abdullah.naser\AppData\Local\Programs\Python\Python312\Lib\site-packages\paramiko\client.py", line 386, in connect
    sock.connect(addr)
TimeoutError: timed out

During handling of the above exception, another exception occurred:

Traceback (most recent call last):
  File "C:\Users\abdullah.naser\AppData\Local\Programs\Python\Python312\Lib\site-packages\napalm\base\base.py", line 114, in _netmiko_open
    self._netmiko_device = ConnectHandler(
                           ^^^^^^^^^^^^^^^
  File "C:\Users\abdullah.naser\AppData\Local\Programs\Python\Python312\Lib\site-packages\netmiko\ssh_dispatcher.py", line 399, in ConnectHandler
    return ConnectionClass(*args, **kwargs)
           ^^^^^^^^^^^^^^^^^^^^^^^^^^^^^^^^
  File "C:\Users\abdullah.naser\AppData\Local\Programs\Python\Python312\Lib\site-packages\netmiko\base_connection.py", line 488, in __init__
    self._open()
  File "C:\Users\abdullah.naser\AppData\Local\Programs\Python\Python312\Lib\site-packages\netmiko\base_connection.py", line 493, in _open
    self.establish_connection()
  File "C:\Users\abdullah.naser\AppData\Local\Programs\Python\Python312\Lib\site-packages\netmiko\base_connection.py", line 1159, in establish_connection
    raise NetmikoTimeoutException(msg)
netmiko.exceptions.NetmikoTimeoutException: TCP connection to device failed.

Common causes of this problem are:
1. Incorrect hostname or IP address.
2. Wrong TCP port.
3. Intermediate firewall blocking access.

Device settings: cisco_ios 10.99.1.1:22



During handling of the above exception, another exception occurred:

Traceback (most recent call last):
  File "C:\Users\abdullah.naser\AppData\Local\Programs\Python\Python312\Lib\site-packages\nornir\core\task.py", line 99, in start
    r = self.task(self, **self.params)
        ^^^^^^^^^^^^^^^^^^^^^^^^^^^^^^
  File "C:\Users\abdullah.naser\AppData\Local\Programs\Python\Python312\Lib\site-packages\nornir_napalm\plugins\tasks\napalm_get.py", line 32, in napalm_get
    device = task.host.get_connection(CONNECTION_NAME, task.nornir.config)
             ^^^^^^^^^^^^^^^^^^^^^^^^^^^^^^^^^^^^^^^^^^^^^^^^^^^^^^^^^^^^^
  File "C:\Users\abdullah.naser\AppData\Local\Programs\Python\Python312\Lib\site-packages\nornir\core\inventory.py", line 494, in get_connection
    self.open_connection(
  File "C:\Users\abdullah.naser\AppData\Local\Programs\Python\Python312\Lib\site-packages\nornir\core\inventory.py", line 546, in open_connection
    conn_obj.open(
  File "C:\Users\abdullah.naser\AppData\Local\Programs\Python\Python312\Lib\site-packages\nornir_napalm\plugins\connections\__init__.py", line 57, in open
    connection.open()
  File "C:\Users\abdullah.naser\AppData\Local\Programs\Python\Python312\Lib\site-packages\napalm\ios\ios.py", line 172, in open
    self.device = self._netmiko_open(
                  ^^^^^^^^^^^^^^^^^^^
  File "C:\Users\abdullah.naser\AppData\Local\Programs\Python\Python312\Lib\site-packages\napalm\base\base.py", line 123, in _netmiko_open
    raise ConnectionException("Cannot connect to {}".format(self.hostname))
napalm.base.exceptions.ConnectionException: Cannot connect to 10.99.1.1

2024-02-21 17:14:44,661 -  nornir.core -     INFO -        run() - Running task 'napalm_get' with args {'getters': ['facts', 'interfaces', 'interfaces_ip']} on 2 hosts
2024-02-21 17:14:54,681 - nornir.core.task -    ERROR -      start() - Host 'Group2-Router1': task 'napalm_get' failed with traceback:
Traceback (most recent call last):
  File "C:\Users\abdullah.naser\AppData\Local\Programs\Python\Python312\Lib\site-packages\netmiko\base_connection.py", line 1137, in establish_connection
    self.remote_conn_pre.connect(**ssh_connect_params)
  File "C:\Users\abdullah.naser\AppData\Local\Programs\Python\Python312\Lib\site-packages\paramiko\client.py", line 386, in connect
    sock.connect(addr)
TimeoutError: timed out

During handling of the above exception, another exception occurred:

Traceback (most recent call last):
  File "C:\Users\abdullah.naser\AppData\Local\Programs\Python\Python312\Lib\site-packages\napalm\base\base.py", line 114, in _netmiko_open
    self._netmiko_device = ConnectHandler(
                           ^^^^^^^^^^^^^^^
  File "C:\Users\abdullah.naser\AppData\Local\Programs\Python\Python312\Lib\site-packages\netmiko\ssh_dispatcher.py", line 399, in ConnectHandler
    return ConnectionClass(*args, **kwargs)
           ^^^^^^^^^^^^^^^^^^^^^^^^^^^^^^^^
  File "C:\Users\abdullah.naser\AppData\Local\Programs\Python\Python312\Lib\site-packages\netmiko\base_connection.py", line 488, in __init__
    self._open()
  File "C:\Users\abdullah.naser\AppData\Local\Programs\Python\Python312\Lib\site-packages\netmiko\base_connection.py", line 493, in _open
    self.establish_connection()
  File "C:\Users\abdullah.naser\AppData\Local\Programs\Python\Python312\Lib\site-packages\netmiko\base_connection.py", line 1159, in establish_connection
    raise NetmikoTimeoutException(msg)
netmiko.exceptions.NetmikoTimeoutException: TCP connection to device failed.

Common causes of this problem are:
1. Incorrect hostname or IP address.
2. Wrong TCP port.
3. Intermediate firewall blocking access.

Device settings: cisco_ios 10.99.2.1:22



During handling of the above exception, another exception occurred:

Traceback (most recent call last):
  File "C:\Users\abdullah.naser\AppData\Local\Programs\Python\Python312\Lib\site-packages\nornir\core\task.py", line 99, in start
    r = self.task(self, **self.params)
        ^^^^^^^^^^^^^^^^^^^^^^^^^^^^^^
  File "C:\Users\abdullah.naser\AppData\Local\Programs\Python\Python312\Lib\site-packages\nornir_napalm\plugins\tasks\napalm_get.py", line 32, in napalm_get
    device = task.host.get_connection(CONNECTION_NAME, task.nornir.config)
             ^^^^^^^^^^^^^^^^^^^^^^^^^^^^^^^^^^^^^^^^^^^^^^^^^^^^^^^^^^^^^
  File "C:\Users\abdullah.naser\AppData\Local\Programs\Python\Python312\Lib\site-packages\nornir\core\inventory.py", line 494, in get_connection
    self.open_connection(
  File "C:\Users\abdullah.naser\AppData\Local\Programs\Python\Python312\Lib\site-packages\nornir\core\inventory.py", line 546, in open_connection
    conn_obj.open(
  File "C:\Users\abdullah.naser\AppData\Local\Programs\Python\Python312\Lib\site-packages\nornir_napalm\plugins\connections\__init__.py", line 57, in open
    connection.open()
  File "C:\Users\abdullah.naser\AppData\Local\Programs\Python\Python312\Lib\site-packages\napalm\ios\ios.py", line 172, in open
    self.device = self._netmiko_open(
                  ^^^^^^^^^^^^^^^^^^^
  File "C:\Users\abdullah.naser\AppData\Local\Programs\Python\Python312\Lib\site-packages\napalm\base\base.py", line 123, in _netmiko_open
    raise ConnectionException("Cannot connect to {}".format(self.hostname))
napalm.base.exceptions.ConnectionException: Cannot connect to 10.99.2.1

2024-02-21 17:16:27,530 -  nornir.core -     INFO -        run() - Running task 'napalm_get' with args {'getters': ['facts', 'interfaces', 'interfaces_ip']} on 2 hosts
2024-02-21 17:16:31,764 -  nornir.core -     INFO -        run() - Running task 'napalm_get' with args {'getters': ['facts', 'interfaces', 'interfaces_ip']} on 2 hosts
2024-02-21 17:16:56,873 -  nornir.core -     INFO -        run() - Running task 'napalm_get' with args {'getters': ['facts', 'interfaces', 'interfaces_ip']} on 2 hosts
2024-02-21 17:18:22,336 -  nornir.core -     INFO -        run() - Running task 'napalm_get' with args {'getters': ['facts', 'interfaces', 'interfaces_ip']} on 2 hosts
2024-02-21 17:23:05,179 -  nornir.core -     INFO -        run() - Running task 'napalm_get' with args {'getters': ['facts', 'interfaces', 'interfaces_ip']} on 5 hosts
2024-02-21 17:23:15,201 - nornir.core.task -    ERROR -      start() - Host 'Group4-Router1': task 'napalm_get' failed with traceback:
Traceback (most recent call last):
  File "C:\Users\abdullah.naser\AppData\Local\Programs\Python\Python312\Lib\site-packages\netmiko\base_connection.py", line 1137, in establish_connection
    self.remote_conn_pre.connect(**ssh_connect_params)
  File "C:\Users\abdullah.naser\AppData\Local\Programs\Python\Python312\Lib\site-packages\paramiko\client.py", line 386, in connect
    sock.connect(addr)
TimeoutError: timed out

During handling of the above exception, another exception occurred:

Traceback (most recent call last):
  File "C:\Users\abdullah.naser\AppData\Local\Programs\Python\Python312\Lib\site-packages\napalm\base\base.py", line 114, in _netmiko_open
    self._netmiko_device = ConnectHandler(
                           ^^^^^^^^^^^^^^^
  File "C:\Users\abdullah.naser\AppData\Local\Programs\Python\Python312\Lib\site-packages\netmiko\ssh_dispatcher.py", line 399, in ConnectHandler
    return ConnectionClass(*args, **kwargs)
           ^^^^^^^^^^^^^^^^^^^^^^^^^^^^^^^^
  File "C:\Users\abdullah.naser\AppData\Local\Programs\Python\Python312\Lib\site-packages\netmiko\base_connection.py", line 488, in __init__
    self._open()
  File "C:\Users\abdullah.naser\AppData\Local\Programs\Python\Python312\Lib\site-packages\netmiko\base_connection.py", line 493, in _open
    self.establish_connection()
  File "C:\Users\abdullah.naser\AppData\Local\Programs\Python\Python312\Lib\site-packages\netmiko\base_connection.py", line 1159, in establish_connection
    raise NetmikoTimeoutException(msg)
netmiko.exceptions.NetmikoTimeoutException: TCP connection to device failed.

Common causes of this problem are:
1. Incorrect hostname or IP address.
2. Wrong TCP port.
3. Intermediate firewall blocking access.

Device settings: cisco_ios 10.99.4.1:22



During handling of the above exception, another exception occurred:

Traceback (most recent call last):
  File "C:\Users\abdullah.naser\AppData\Local\Programs\Python\Python312\Lib\site-packages\nornir\core\task.py", line 99, in start
    r = self.task(self, **self.params)
        ^^^^^^^^^^^^^^^^^^^^^^^^^^^^^^
  File "C:\Users\abdullah.naser\AppData\Local\Programs\Python\Python312\Lib\site-packages\nornir_napalm\plugins\tasks\napalm_get.py", line 32, in napalm_get
    device = task.host.get_connection(CONNECTION_NAME, task.nornir.config)
             ^^^^^^^^^^^^^^^^^^^^^^^^^^^^^^^^^^^^^^^^^^^^^^^^^^^^^^^^^^^^^
  File "C:\Users\abdullah.naser\AppData\Local\Programs\Python\Python312\Lib\site-packages\nornir\core\inventory.py", line 494, in get_connection
    self.open_connection(
  File "C:\Users\abdullah.naser\AppData\Local\Programs\Python\Python312\Lib\site-packages\nornir\core\inventory.py", line 546, in open_connection
    conn_obj.open(
  File "C:\Users\abdullah.naser\AppData\Local\Programs\Python\Python312\Lib\site-packages\nornir_napalm\plugins\connections\__init__.py", line 57, in open
    connection.open()
  File "C:\Users\abdullah.naser\AppData\Local\Programs\Python\Python312\Lib\site-packages\napalm\ios\ios.py", line 172, in open
    self.device = self._netmiko_open(
                  ^^^^^^^^^^^^^^^^^^^
  File "C:\Users\abdullah.naser\AppData\Local\Programs\Python\Python312\Lib\site-packages\napalm\base\base.py", line 123, in _netmiko_open
    raise ConnectionException("Cannot connect to {}".format(self.hostname))
napalm.base.exceptions.ConnectionException: Cannot connect to 10.99.4.1

2024-02-21 17:23:15,203 - nornir.core.task -    ERROR -      start() - Host 'Group5-Router1': task 'napalm_get' failed with traceback:
Traceback (most recent call last):
  File "C:\Users\abdullah.naser\AppData\Local\Programs\Python\Python312\Lib\site-packages\netmiko\base_connection.py", line 1137, in establish_connection
    self.remote_conn_pre.connect(**ssh_connect_params)
  File "C:\Users\abdullah.naser\AppData\Local\Programs\Python\Python312\Lib\site-packages\paramiko\client.py", line 386, in connect
    sock.connect(addr)
TimeoutError: timed out

During handling of the above exception, another exception occurred:

Traceback (most recent call last):
  File "C:\Users\abdullah.naser\AppData\Local\Programs\Python\Python312\Lib\site-packages\napalm\base\base.py", line 114, in _netmiko_open
    self._netmiko_device = ConnectHandler(
                           ^^^^^^^^^^^^^^^
  File "C:\Users\abdullah.naser\AppData\Local\Programs\Python\Python312\Lib\site-packages\netmiko\ssh_dispatcher.py", line 399, in ConnectHandler
    return ConnectionClass(*args, **kwargs)
           ^^^^^^^^^^^^^^^^^^^^^^^^^^^^^^^^
  File "C:\Users\abdullah.naser\AppData\Local\Programs\Python\Python312\Lib\site-packages\netmiko\base_connection.py", line 488, in __init__
    self._open()
  File "C:\Users\abdullah.naser\AppData\Local\Programs\Python\Python312\Lib\site-packages\netmiko\base_connection.py", line 493, in _open
    self.establish_connection()
  File "C:\Users\abdullah.naser\AppData\Local\Programs\Python\Python312\Lib\site-packages\netmiko\base_connection.py", line 1159, in establish_connection
    raise NetmikoTimeoutException(msg)
netmiko.exceptions.NetmikoTimeoutException: TCP connection to device failed.

Common causes of this problem are:
1. Incorrect hostname or IP address.
2. Wrong TCP port.
3. Intermediate firewall blocking access.

Device settings: cisco_ios 10.99.5.1:22



During handling of the above exception, another exception occurred:

Traceback (most recent call last):
  File "C:\Users\abdullah.naser\AppData\Local\Programs\Python\Python312\Lib\site-packages\nornir\core\task.py", line 99, in start
    r = self.task(self, **self.params)
        ^^^^^^^^^^^^^^^^^^^^^^^^^^^^^^
  File "C:\Users\abdullah.naser\AppData\Local\Programs\Python\Python312\Lib\site-packages\nornir_napalm\plugins\tasks\napalm_get.py", line 32, in napalm_get
    device = task.host.get_connection(CONNECTION_NAME, task.nornir.config)
             ^^^^^^^^^^^^^^^^^^^^^^^^^^^^^^^^^^^^^^^^^^^^^^^^^^^^^^^^^^^^^
  File "C:\Users\abdullah.naser\AppData\Local\Programs\Python\Python312\Lib\site-packages\nornir\core\inventory.py", line 494, in get_connection
    self.open_connection(
  File "C:\Users\abdullah.naser\AppData\Local\Programs\Python\Python312\Lib\site-packages\nornir\core\inventory.py", line 546, in open_connection
    conn_obj.open(
  File "C:\Users\abdullah.naser\AppData\Local\Programs\Python\Python312\Lib\site-packages\nornir_napalm\plugins\connections\__init__.py", line 57, in open
    connection.open()
  File "C:\Users\abdullah.naser\AppData\Local\Programs\Python\Python312\Lib\site-packages\napalm\ios\ios.py", line 172, in open
    self.device = self._netmiko_open(
                  ^^^^^^^^^^^^^^^^^^^
  File "C:\Users\abdullah.naser\AppData\Local\Programs\Python\Python312\Lib\site-packages\napalm\base\base.py", line 123, in _netmiko_open
    raise ConnectionException("Cannot connect to {}".format(self.hostname))
napalm.base.exceptions.ConnectionException: Cannot connect to 10.99.5.1

2024-02-21 17:23:15,204 - nornir.core.task -    ERROR -      start() - Host 'Group3-Router1': task 'napalm_get' failed with traceback:
Traceback (most recent call last):
  File "C:\Users\abdullah.naser\AppData\Local\Programs\Python\Python312\Lib\site-packages\netmiko\base_connection.py", line 1137, in establish_connection
    self.remote_conn_pre.connect(**ssh_connect_params)
  File "C:\Users\abdullah.naser\AppData\Local\Programs\Python\Python312\Lib\site-packages\paramiko\client.py", line 386, in connect
    sock.connect(addr)
TimeoutError: timed out

During handling of the above exception, another exception occurred:

Traceback (most recent call last):
  File "C:\Users\abdullah.naser\AppData\Local\Programs\Python\Python312\Lib\site-packages\napalm\base\base.py", line 114, in _netmiko_open
    self._netmiko_device = ConnectHandler(
                           ^^^^^^^^^^^^^^^
  File "C:\Users\abdullah.naser\AppData\Local\Programs\Python\Python312\Lib\site-packages\netmiko\ssh_dispatcher.py", line 399, in ConnectHandler
    return ConnectionClass(*args, **kwargs)
           ^^^^^^^^^^^^^^^^^^^^^^^^^^^^^^^^
  File "C:\Users\abdullah.naser\AppData\Local\Programs\Python\Python312\Lib\site-packages\netmiko\base_connection.py", line 488, in __init__
    self._open()
  File "C:\Users\abdullah.naser\AppData\Local\Programs\Python\Python312\Lib\site-packages\netmiko\base_connection.py", line 493, in _open
    self.establish_connection()
  File "C:\Users\abdullah.naser\AppData\Local\Programs\Python\Python312\Lib\site-packages\netmiko\base_connection.py", line 1159, in establish_connection
    raise NetmikoTimeoutException(msg)
netmiko.exceptions.NetmikoTimeoutException: TCP connection to device failed.

Common causes of this problem are:
1. Incorrect hostname or IP address.
2. Wrong TCP port.
3. Intermediate firewall blocking access.

Device settings: cisco_ios 10.99.3.1:22



During handling of the above exception, another exception occurred:

Traceback (most recent call last):
  File "C:\Users\abdullah.naser\AppData\Local\Programs\Python\Python312\Lib\site-packages\nornir\core\task.py", line 99, in start
    r = self.task(self, **self.params)
        ^^^^^^^^^^^^^^^^^^^^^^^^^^^^^^
  File "C:\Users\abdullah.naser\AppData\Local\Programs\Python\Python312\Lib\site-packages\nornir_napalm\plugins\tasks\napalm_get.py", line 32, in napalm_get
    device = task.host.get_connection(CONNECTION_NAME, task.nornir.config)
             ^^^^^^^^^^^^^^^^^^^^^^^^^^^^^^^^^^^^^^^^^^^^^^^^^^^^^^^^^^^^^
  File "C:\Users\abdullah.naser\AppData\Local\Programs\Python\Python312\Lib\site-packages\nornir\core\inventory.py", line 494, in get_connection
    self.open_connection(
  File "C:\Users\abdullah.naser\AppData\Local\Programs\Python\Python312\Lib\site-packages\nornir\core\inventory.py", line 546, in open_connection
    conn_obj.open(
  File "C:\Users\abdullah.naser\AppData\Local\Programs\Python\Python312\Lib\site-packages\nornir_napalm\plugins\connections\__init__.py", line 57, in open
    connection.open()
  File "C:\Users\abdullah.naser\AppData\Local\Programs\Python\Python312\Lib\site-packages\napalm\ios\ios.py", line 172, in open
    self.device = self._netmiko_open(
                  ^^^^^^^^^^^^^^^^^^^
  File "C:\Users\abdullah.naser\AppData\Local\Programs\Python\Python312\Lib\site-packages\napalm\base\base.py", line 123, in _netmiko_open
    raise ConnectionException("Cannot connect to {}".format(self.hostname))
napalm.base.exceptions.ConnectionException: Cannot connect to 10.99.3.1

2024-02-21 17:24:24,489 -  nornir.core -     INFO -        run() - Running task 'napalm_get' with args {'getters': ['facts', 'interfaces', 'interfaces_ip']} on 5 hosts
2024-02-21 17:24:34,512 - nornir.core.task -    ERROR -      start() - Host 'Group5-Router1': task 'napalm_get' failed with traceback:
Traceback (most recent call last):
  File "C:\Users\abdullah.naser\AppData\Local\Programs\Python\Python312\Lib\site-packages\netmiko\base_connection.py", line 1137, in establish_connection
    self.remote_conn_pre.connect(**ssh_connect_params)
  File "C:\Users\abdullah.naser\AppData\Local\Programs\Python\Python312\Lib\site-packages\paramiko\client.py", line 386, in connect
    sock.connect(addr)
TimeoutError: timed out

During handling of the above exception, another exception occurred:

Traceback (most recent call last):
  File "C:\Users\abdullah.naser\AppData\Local\Programs\Python\Python312\Lib\site-packages\napalm\base\base.py", line 114, in _netmiko_open
    self._netmiko_device = ConnectHandler(
                           ^^^^^^^^^^^^^^^
  File "C:\Users\abdullah.naser\AppData\Local\Programs\Python\Python312\Lib\site-packages\netmiko\ssh_dispatcher.py", line 399, in ConnectHandler
    return ConnectionClass(*args, **kwargs)
           ^^^^^^^^^^^^^^^^^^^^^^^^^^^^^^^^
  File "C:\Users\abdullah.naser\AppData\Local\Programs\Python\Python312\Lib\site-packages\netmiko\base_connection.py", line 488, in __init__
    self._open()
  File "C:\Users\abdullah.naser\AppData\Local\Programs\Python\Python312\Lib\site-packages\netmiko\base_connection.py", line 493, in _open
    self.establish_connection()
  File "C:\Users\abdullah.naser\AppData\Local\Programs\Python\Python312\Lib\site-packages\netmiko\base_connection.py", line 1159, in establish_connection
    raise NetmikoTimeoutException(msg)
netmiko.exceptions.NetmikoTimeoutException: TCP connection to device failed.

Common causes of this problem are:
1. Incorrect hostname or IP address.
2. Wrong TCP port.
3. Intermediate firewall blocking access.

Device settings: cisco_ios 10.99.5.1:22



During handling of the above exception, another exception occurred:

Traceback (most recent call last):
  File "C:\Users\abdullah.naser\AppData\Local\Programs\Python\Python312\Lib\site-packages\nornir\core\task.py", line 99, in start
    r = self.task(self, **self.params)
        ^^^^^^^^^^^^^^^^^^^^^^^^^^^^^^
  File "C:\Users\abdullah.naser\AppData\Local\Programs\Python\Python312\Lib\site-packages\nornir_napalm\plugins\tasks\napalm_get.py", line 32, in napalm_get
    device = task.host.get_connection(CONNECTION_NAME, task.nornir.config)
             ^^^^^^^^^^^^^^^^^^^^^^^^^^^^^^^^^^^^^^^^^^^^^^^^^^^^^^^^^^^^^
  File "C:\Users\abdullah.naser\AppData\Local\Programs\Python\Python312\Lib\site-packages\nornir\core\inventory.py", line 494, in get_connection
    self.open_connection(
  File "C:\Users\abdullah.naser\AppData\Local\Programs\Python\Python312\Lib\site-packages\nornir\core\inventory.py", line 546, in open_connection
    conn_obj.open(
  File "C:\Users\abdullah.naser\AppData\Local\Programs\Python\Python312\Lib\site-packages\nornir_napalm\plugins\connections\__init__.py", line 57, in open
    connection.open()
  File "C:\Users\abdullah.naser\AppData\Local\Programs\Python\Python312\Lib\site-packages\napalm\ios\ios.py", line 172, in open
    self.device = self._netmiko_open(
                  ^^^^^^^^^^^^^^^^^^^
  File "C:\Users\abdullah.naser\AppData\Local\Programs\Python\Python312\Lib\site-packages\napalm\base\base.py", line 123, in _netmiko_open
    raise ConnectionException("Cannot connect to {}".format(self.hostname))
napalm.base.exceptions.ConnectionException: Cannot connect to 10.99.5.1

2024-02-21 17:24:34,513 - nornir.core.task -    ERROR -      start() - Host 'Group4-Router1': task 'napalm_get' failed with traceback:
Traceback (most recent call last):
  File "C:\Users\abdullah.naser\AppData\Local\Programs\Python\Python312\Lib\site-packages\netmiko\base_connection.py", line 1137, in establish_connection
    self.remote_conn_pre.connect(**ssh_connect_params)
  File "C:\Users\abdullah.naser\AppData\Local\Programs\Python\Python312\Lib\site-packages\paramiko\client.py", line 386, in connect
    sock.connect(addr)
TimeoutError: timed out

During handling of the above exception, another exception occurred:

Traceback (most recent call last):
  File "C:\Users\abdullah.naser\AppData\Local\Programs\Python\Python312\Lib\site-packages\napalm\base\base.py", line 114, in _netmiko_open
    self._netmiko_device = ConnectHandler(
                           ^^^^^^^^^^^^^^^
  File "C:\Users\abdullah.naser\AppData\Local\Programs\Python\Python312\Lib\site-packages\netmiko\ssh_dispatcher.py", line 399, in ConnectHandler
    return ConnectionClass(*args, **kwargs)
           ^^^^^^^^^^^^^^^^^^^^^^^^^^^^^^^^
  File "C:\Users\abdullah.naser\AppData\Local\Programs\Python\Python312\Lib\site-packages\netmiko\base_connection.py", line 488, in __init__
    self._open()
  File "C:\Users\abdullah.naser\AppData\Local\Programs\Python\Python312\Lib\site-packages\netmiko\base_connection.py", line 493, in _open
    self.establish_connection()
  File "C:\Users\abdullah.naser\AppData\Local\Programs\Python\Python312\Lib\site-packages\netmiko\base_connection.py", line 1159, in establish_connection
    raise NetmikoTimeoutException(msg)
netmiko.exceptions.NetmikoTimeoutException: TCP connection to device failed.

Common causes of this problem are:
1. Incorrect hostname or IP address.
2. Wrong TCP port.
3. Intermediate firewall blocking access.

Device settings: cisco_ios 10.99.4.1:22



During handling of the above exception, another exception occurred:

Traceback (most recent call last):
  File "C:\Users\abdullah.naser\AppData\Local\Programs\Python\Python312\Lib\site-packages\nornir\core\task.py", line 99, in start
    r = self.task(self, **self.params)
        ^^^^^^^^^^^^^^^^^^^^^^^^^^^^^^
  File "C:\Users\abdullah.naser\AppData\Local\Programs\Python\Python312\Lib\site-packages\nornir_napalm\plugins\tasks\napalm_get.py", line 32, in napalm_get
    device = task.host.get_connection(CONNECTION_NAME, task.nornir.config)
             ^^^^^^^^^^^^^^^^^^^^^^^^^^^^^^^^^^^^^^^^^^^^^^^^^^^^^^^^^^^^^
  File "C:\Users\abdullah.naser\AppData\Local\Programs\Python\Python312\Lib\site-packages\nornir\core\inventory.py", line 494, in get_connection
    self.open_connection(
  File "C:\Users\abdullah.naser\AppData\Local\Programs\Python\Python312\Lib\site-packages\nornir\core\inventory.py", line 546, in open_connection
    conn_obj.open(
  File "C:\Users\abdullah.naser\AppData\Local\Programs\Python\Python312\Lib\site-packages\nornir_napalm\plugins\connections\__init__.py", line 57, in open
    connection.open()
  File "C:\Users\abdullah.naser\AppData\Local\Programs\Python\Python312\Lib\site-packages\napalm\ios\ios.py", line 172, in open
    self.device = self._netmiko_open(
                  ^^^^^^^^^^^^^^^^^^^
  File "C:\Users\abdullah.naser\AppData\Local\Programs\Python\Python312\Lib\site-packages\napalm\base\base.py", line 123, in _netmiko_open
    raise ConnectionException("Cannot connect to {}".format(self.hostname))
napalm.base.exceptions.ConnectionException: Cannot connect to 10.99.4.1

2024-02-21 17:24:34,514 - nornir.core.task -    ERROR -      start() - Host 'Group3-Router1': task 'napalm_get' failed with traceback:
Traceback (most recent call last):
  File "C:\Users\abdullah.naser\AppData\Local\Programs\Python\Python312\Lib\site-packages\netmiko\base_connection.py", line 1137, in establish_connection
    self.remote_conn_pre.connect(**ssh_connect_params)
  File "C:\Users\abdullah.naser\AppData\Local\Programs\Python\Python312\Lib\site-packages\paramiko\client.py", line 386, in connect
    sock.connect(addr)
TimeoutError: timed out

During handling of the above exception, another exception occurred:

Traceback (most recent call last):
  File "C:\Users\abdullah.naser\AppData\Local\Programs\Python\Python312\Lib\site-packages\napalm\base\base.py", line 114, in _netmiko_open
    self._netmiko_device = ConnectHandler(
                           ^^^^^^^^^^^^^^^
  File "C:\Users\abdullah.naser\AppData\Local\Programs\Python\Python312\Lib\site-packages\netmiko\ssh_dispatcher.py", line 399, in ConnectHandler
    return ConnectionClass(*args, **kwargs)
           ^^^^^^^^^^^^^^^^^^^^^^^^^^^^^^^^
  File "C:\Users\abdullah.naser\AppData\Local\Programs\Python\Python312\Lib\site-packages\netmiko\base_connection.py", line 488, in __init__
    self._open()
  File "C:\Users\abdullah.naser\AppData\Local\Programs\Python\Python312\Lib\site-packages\netmiko\base_connection.py", line 493, in _open
    self.establish_connection()
  File "C:\Users\abdullah.naser\AppData\Local\Programs\Python\Python312\Lib\site-packages\netmiko\base_connection.py", line 1159, in establish_connection
    raise NetmikoTimeoutException(msg)
netmiko.exceptions.NetmikoTimeoutException: TCP connection to device failed.

Common causes of this problem are:
1. Incorrect hostname or IP address.
2. Wrong TCP port.
3. Intermediate firewall blocking access.

Device settings: cisco_ios 10.99.3.1:22



During handling of the above exception, another exception occurred:

Traceback (most recent call last):
  File "C:\Users\abdullah.naser\AppData\Local\Programs\Python\Python312\Lib\site-packages\nornir\core\task.py", line 99, in start
    r = self.task(self, **self.params)
        ^^^^^^^^^^^^^^^^^^^^^^^^^^^^^^
  File "C:\Users\abdullah.naser\AppData\Local\Programs\Python\Python312\Lib\site-packages\nornir_napalm\plugins\tasks\napalm_get.py", line 32, in napalm_get
    device = task.host.get_connection(CONNECTION_NAME, task.nornir.config)
             ^^^^^^^^^^^^^^^^^^^^^^^^^^^^^^^^^^^^^^^^^^^^^^^^^^^^^^^^^^^^^
  File "C:\Users\abdullah.naser\AppData\Local\Programs\Python\Python312\Lib\site-packages\nornir\core\inventory.py", line 494, in get_connection
    self.open_connection(
  File "C:\Users\abdullah.naser\AppData\Local\Programs\Python\Python312\Lib\site-packages\nornir\core\inventory.py", line 546, in open_connection
    conn_obj.open(
  File "C:\Users\abdullah.naser\AppData\Local\Programs\Python\Python312\Lib\site-packages\nornir_napalm\plugins\connections\__init__.py", line 57, in open
    connection.open()
  File "C:\Users\abdullah.naser\AppData\Local\Programs\Python\Python312\Lib\site-packages\napalm\ios\ios.py", line 172, in open
    self.device = self._netmiko_open(
                  ^^^^^^^^^^^^^^^^^^^
  File "C:\Users\abdullah.naser\AppData\Local\Programs\Python\Python312\Lib\site-packages\napalm\base\base.py", line 123, in _netmiko_open
    raise ConnectionException("Cannot connect to {}".format(self.hostname))
napalm.base.exceptions.ConnectionException: Cannot connect to 10.99.3.1

2024-02-21 17:27:01,570 -  nornir.core -     INFO -        run() - Running task 'napalm_get' with args {'getters': ['facts', 'interfaces', 'interfaces_ip']} on 2 hosts
